<?xml version="1.0" ?>
<!-- =================================================================================== -->
<!-- |    This document was autogenerated by xacro from ester.urdf.xacro               | -->
<!-- |    EDITING THIS FILE BY HAND IS NOT RECOMMENDED                                 | -->
<!-- =================================================================================== -->
<robot name="ester">
  <gazebo>
    <plugin filename="libgazebo_ros_control.so" name="gazebo_ros_control">
      <robotNamespace>/ester</robotNamespace>
    </plugin>
    <selfCollide>false</selfCollide>
  </gazebo>
  <!-- Dummy parent link for Gazebo -->
  <link name="base_link"/>
  <link name="spine_center_link">
    <inertial>
      <mass value="0.412971"/>
      <origin xyz="-0.000375 -0.001924 -0.03454"/>
      <inertia ixx="9.067E-04" ixy="-8.901E-05" ixz="7.674E-06" iyy="5.927E-04" iyz="4.114E-06" izz="1.033E-03"/>
    </inertial>
    <visual>
      <origin rpy="0 0 0" xyz="0 0 0"/>
      <geometry>
        <mesh filename="../meshes/spine/spine_center.stl" scale="0.001 0.001 0.001"/>
      </geometry>
    </visual>
    <collision>
      <origin rpy="0 0 0" xyz="0 0 0"/>
      <geometry>
        <mesh filename="../meshes/spine/spine_center.stl" scale="0.001 0.001 0.001"/>
      </geometry>
    </collision>
  </link>
  <joint name="spine_center_joint" type="fixed">
    <origin rpy="0 0 0" xyz="0 0 0"/>
    <parent link="base_link"/>
    <child link="spine_center_link"/>
  </joint>
  <link name="front_spine_pitch_link">
    <inertial>
      <mass value="0.135102"/>
      <origin xyz="-0.007075 -0.000188 -0.006485"/>
      <inertia ixx="5.528E-05" ixy="3.264E-07" ixz="8.008E-06" iyy="8.590E-05" iyz="2.381E-07" izz="6.630E-05"/>
    </inertial>
    <visual>
      <origin xyz="0 0 0"/>
      <geometry>
        <mesh filename="../meshes/spine/front_spine_pitch.stl" scale="0.001 0.001 0.001"/>
      </geometry>
    </visual>
    <collision>
      <origin xyz="0 0 0"/>
      <geometry>
        <mesh filename="../meshes/spine/front_spine_pitch.stl" scale="0.001 0.001 0.001"/>
      </geometry>
    </collision>
  </link>
  <joint name="front_spine_pitch_joint" type="revolute">
    <origin rpy="0 0 0" xyz="0.045 0.0 -0.015"/>
    <axis xyz="0 1 0"/>
    <limit effort="4.32" lower="-0.2617993877991494" upper="0.2617993877991494" velocity="46.875"/>
    <dynamics damping="0.05" friction="0.1"/>
    <parent link="spine_center_link"/>
    <child link="front_spine_pitch_link"/>
  </joint>
  <transmission name="front_spine_pitch_transmission">
    <type>transmission_interface/SimpleTransmission</type>
    <joint name="front_spine_pitch_joint">
      <hardwareInterface>hardware_interface/EffortJointInterface</hardwareInterface>
    </joint>
    <actuator name="front_spine_pitch_motor">
      <hardwareInterface>hardware_interface/EffortJointInterface</hardwareInterface>
      <mechanicalReduction>1</mechanicalReduction>
    </actuator>
  </transmission>
  <link name="rear_spine_pitch_link">
    <inertial>
      <mass value="0.131658"/>
      <origin xyz="-0.006128 0.00016 -0.007237"/>
      <inertia ixx="5.096E-05" ixy="-3.566E-07" ixz="4.115E-06" iyy="7.796E-05" iyz="-2.003E-07" izz="6.027E-05"/>
    </inertial>
    <visual>
      <origin xyz="0 0 0"/>
      <geometry>
        <mesh filename="../meshes/spine/rear_spine_pitch.stl" scale="0.001 0.001 0.001"/>
      </geometry>
    </visual>
    <collision>
      <origin xyz="0 0 0"/>
      <geometry>
        <mesh filename="../meshes/spine/rear_spine_pitch.stl" scale="0.001 0.001 0.001"/>
      </geometry>
    </collision>
  </link>
  <joint name="rear_spine_pitch_joint" type="revolute">
    <origin rpy="0 0 0" xyz="-0.045 0.0 -0.015"/>
    <axis xyz="0 1 0"/>
    <limit effort="4.32" lower="-0.2617993877991494" upper="0.2617993877991494" velocity="46.875"/>
    <dynamics damping="0.05" friction="0.1"/>
    <parent link="spine_center_link"/>
    <child link="rear_spine_pitch_link"/>
  </joint>
  <transmission name="rear_spine_pitch_transmission">
    <type>transmission_interface/SimpleTransmission</type>
    <joint name="rear_spine_pitch_joint">
      <hardwareInterface>hardware_interface/EffortJointInterface</hardwareInterface>
    </joint>
    <actuator name="rear_spine_pitch_motor">
      <hardwareInterface>hardware_interface/EffortJointInterface</hardwareInterface>
      <mechanicalReduction>1</mechanicalReduction>
    </actuator>
  </transmission>
  <link name="front_spine_yaw_link">
    <inertial>
      <mass value="0.155204"/>
      <origin xyz="0.038563 0.001038 -0.081837"/>
      <inertia ixx="7.814E-04" ixy="-1.445E-06" ixz="-6.187E-05" iyy="6.385E-05" iyz="-4.799E-06" izz="3.198E-04"/>
    </inertial>
    <visual>
      <origin xyz="0 0 0"/>
      <geometry>
        <mesh filename="../meshes/spine/front_spine_yaw.stl" scale="0.001 0.001 0.001"/>
      </geometry>
    </visual>
    <collision>
      <origin xyz="0 0 0"/>
      <geometry>
        <mesh filename="../meshes/spine/front_spine_yaw.stl" scale="0.001 0.001 0.001"/>
      </geometry>
    </collision>
  </link>
  <joint name="front_spine_yaw_joint" type="revolute">
    <origin rpy="0 0 0" xyz="0 0 0.02115"/>
    <axis xyz="0 0 1"/>
    <limit effort="2.43" lower="-0.2617993877991494" upper="0.2617993877991494" velocity="83.33333333333333"/>
    <dynamics damping="0.05" friction="0.1"/>
    <parent link="front_spine_pitch_link"/>
    <child link="front_spine_yaw_link"/>
  </joint>
  <transmission name="front_spine_yaw_transmission">
    <type>transmission_interface/SimpleTransmission</type>
    <joint name="front_spine_yaw_joint">
      <hardwareInterface>hardware_interface/EffortJointInterface</hardwareInterface>
    </joint>
    <actuator name="front_spine_yaw_motor">
      <hardwareInterface>hardware_interface/EffortJointInterface</hardwareInterface>
      <mechanicalReduction>1</mechanicalReduction>
    </actuator>
  </transmission>
  <link name="rear_spine_yaw_link">
    <inertial>
      <mass value="0.1"/>
      <origin xyz="0 0 0"/>
      <inertia ixx="1E-05" ixy="0" ixz="0" iyy="1E-05" iyz="0" izz="1E-05"/>
    </inertial>
  </link>
  <joint name="rear_spine_yaw_joint" type="revolute">
    <origin rpy="0 0 0" xyz="0 0 0.02115"/>
    <axis xyz="0 0 1"/>
    <limit effort="2.43" lower="-0.2617993877991494" upper="0.2617993877991494" velocity="83.33333333333333"/>
    <dynamics damping="0.05" friction="0.1"/>
    <parent link="rear_spine_pitch_link"/>
    <child link="rear_spine_yaw_link"/>
  </joint>
  <transmission name="rear_spine_yaw_transmission">
    <type>transmission_interface/SimpleTransmission</type>
    <joint name="rear_spine_yaw_joint">
      <hardwareInterface>hardware_interface/EffortJointInterface</hardwareInterface>
    </joint>
    <actuator name="rear_spine_yaw_motor">
      <hardwareInterface>hardware_interface/EffortJointInterface</hardwareInterface>
      <mechanicalReduction>1</mechanicalReduction>
    </actuator>
  </transmission>
  <link name="front_left_hip_aa_link">
    <inertial>
      <mass value="0.149885"/>
      <origin xyz="-0.017329 -0.026389 0.014"/>
      <inertia ixx="2.575E-04" ixy="2.519E-05" ixz="7.023E-09" iyy="2.683E-05" iyz="-6.917E-08" izz="2.557E-04"/>
    </inertial>
    <visual>
      <origin rpy="0 0 0" xyz="0 0 0"/>
      <geometry>
        <mesh filename="../meshes/leg/front_hip_aa.stl" scale="0.001 0.001 0.001"/>
      </geometry>
    </visual>
    <collision>
      <origin rpy="0 0 0" xyz="0 0 0"/>
      <geometry>
        <mesh filename="../meshes/leg/front_hip_aa.stl" scale="0.001 0.001 0.001"/>
      </geometry>
    </collision>
  </link>
  <joint name="front_left_hip_aa_joint" type="fixed">
    <origin rpy="0 0.7853981633974483 3.141592653589793" xyz="0.01 -0.024 -0.1065"/>
    <parent link="front_spine_yaw_link"/>
    <child link="front_left_hip_aa_link"/>
  </joint>
  <link name="front_left_hip_fe_link">
    <inertial>
      <mass value="0.139328"/>
      <origin rpy="0 0 3.141592653589793" xyz="0.01808 0.004477 -0.014405"/>
      <inertia ixx="6.080E-05" ixy="-3.521E-06" ixz="2.540E-06" iyy="1.052E-04" iyz="1.247E-05" izz="7.157E-05"/>
    </inertial>
    <visual>
      <origin rpy="0 0 3.141592653589793" xyz="0 0 -0.003"/>
      <geometry>
        <mesh filename="../meshes/leg/front_hip_fe.stl" scale="0.001 0.001 0.001"/>
      </geometry>
    </visual>
    <collision>
      <origin rpy="0 0 3.141592653589793" xyz="0 0 -0.003"/>
      <geometry>
        <mesh filename="../meshes/leg/front_hip_fe.stl" scale="0.001 0.001 0.001"/>
      </geometry>
    </collision>
  </link>
  <joint name="front_left_hip_fe_joint" type="revolute">
    <origin rpy="0 0 3.141592653589793" xyz="-0.083972 -0.0878 0"/>
    <axis xyz="1 0 0"/>
    <limit effort="2.43" lower="-0.17453292519943295" upper="0.7853981633974483" velocity="83.33333333333333"/>
    <dynamics damping="0.05" friction="0.1"/>
    <parent link="front_left_hip_aa_link"/>
    <child link="front_left_hip_fe_link"/>
  </joint>
  <transmission name="front_left_hip_fe_transmission">
    <type>transmission_interface/SimpleTransmission</type>
    <joint name="front_left_hip_fe_joint">
      <hardwareInterface>hardware_interface/EffortJointInterface</hardwareInterface>
    </joint>
    <actuator name="front_left_hip_fe_motor">
      <hardwareInterface>hardware_interface/EffortJointInterface</hardwareInterface>
      <mechanicalReduction>1</mechanicalReduction>
    </actuator>
  </transmission>
  <link name="front_left_upper_leg_link">
    <inertial>
      <mass value="0.158127"/>
      <origin rpy="0 0 1.5707963267948966" xyz="0.0 0.022563 -0.07012"/>
      <inertia ixx="2.824E-04" ixy="4.259E-09" ixz="-6.584E-08" iyy="2.882E-04" iyz="3.543E-05" izz="3.742E-05"/>
    </inertial>
    <visual>
      <origin rpy="0 0 1.5707963267948966" xyz="0 0 0"/>
      <geometry>
        <mesh filename="../meshes/leg/front_upper_leg.stl" scale="0.001 0.001 0.001"/>
      </geometry>
    </visual>
    <collision>
      <origin rpy="0 0 1.5707963267948966" xyz="0 0 0"/>
      <geometry>
        <mesh filename="../meshes/leg/front_upper_leg.stl" scale="0.001 0.001 0.001"/>
      </geometry>
    </collision>
  </link>
  <joint name="front_left_upper_leg_joint" type="revolute">
    <origin rpy="0 0.7853981633974483 0" xyz="0 0.01415 0"/>
    <axis xyz="0 1 0"/>
    <limit effort="4.32" lower="-1.5707963267948966" upper="1.5707963267948966" velocity="46.875"/>
    <dynamics damping="0.05" friction="0.1"/>
    <parent link="front_left_hip_fe_link"/>
    <child link="front_left_upper_leg_link"/>
  </joint>
  <transmission name="front_left_upper_leg_transmission">
    <type>transmission_interface/SimpleTransmission</type>
    <joint name="front_left_upper_leg_joint">
      <hardwareInterface>hardware_interface/EffortJointInterface</hardwareInterface>
    </joint>
    <actuator name="front_left_upper_leg_motor">
      <hardwareInterface>hardware_interface/EffortJointInterface</hardwareInterface>
      <mechanicalReduction>1</mechanicalReduction>
    </actuator>
  </transmission>
  <link name="front_left_lower_leg_link">
    <inertial>
      <mass value="0.023961"/>
      <origin xyz="0 0.00816 -0.044589"/>
      <inertia ixx="3.727E-05" ixy="-5.628E-16" ixz="2.285E-15" iyy="3.709E-05" iyz="-5.027E-06" izz="1.815E-06"/>
    </inertial>
    <visual>
      <origin rpy="0 0 0" xyz="0 0 0"/>
      <geometry>
        <mesh filename="../meshes/leg/front_lower_leg.stl" scale="0.001 0.001 0.001"/>
      </geometry>
    </visual>
    <collision>
      <origin rpy="0 0 0" xyz="0 0 0"/>
      <geometry>
        <mesh filename="../meshes/leg/front_lower_leg.stl" scale="0.001 0.001 0.001"/>
      </geometry>
    </collision>
  </link>
  <joint name="front_left_lower_leg_joint" type="revolute">
    <axis xyz="0 1 0"/>
    <limit effort="4.32" lower="-1.5707963267948966" upper="1.5707963267948966" velocity="46.875"/>
    <dynamics damping="0.05" friction="0.1"/>
    <origin rpy="0 0 0" xyz="0 0.0315 -0.1232"/>
    <parent link="front_left_upper_leg_link"/>
    <child link="front_left_lower_leg_link"/>
  </joint>
  <transmission name="front_left_lower_leg_transmission">
    <type>transmission_interface/SimpleTransmission</type>
    <joint name="front_left_lower_leg_joint">
      <hardwareInterface>hardware_interface/EffortJointInterface</hardwareInterface>
    </joint>
    <actuator name="front_left_lower_leg_motor">
      <hardwareInterface>hardware_interface/EffortJointInterface</hardwareInterface>
      <mechanicalReduction>1</mechanicalReduction>
    </actuator>
  </transmission>
  <link name="front_left_foot_contact_link">
    <inertial>
      <mass value="0.01"/>
      <origin xyz="0 0 0"/>
      <inertia ixx="1e-9" ixy="0.0" ixz="0.0" iyy="1e-9" iyz="0.0" izz="1e-9"/>
    </inertial>
    <visual>
      <origin xyz="0 0 0"/>
      <geometry>
        <sphere radius="0.015"/>
      </geometry>
    </visual>
    <collision>
      <origin xyz="0 0 0"/>
      <geometry>
        <sphere radius="0.015"/>
      </geometry>
    </collision>
  </link>
  <joint name="front_left_foot_contact_joint" type="fixed">
    <origin xyz="0 0 -0.105"/>
    <parent link="front_left_lower_leg_link"/>
    <child link="front_left_foot_contact_link"/>
  </joint>
  <link name="front_right_hip_aa_link">
    <inertial>
      <mass value="0.149885"/>
      <origin xyz="-0.017329 -0.026389 0.014"/>
      <inertia ixx="2.575E-04" ixy="2.519E-05" ixz="7.023E-09" iyy="2.683E-05" iyz="-6.917E-08" izz="2.557E-04"/>
    </inertial>
    <visual>
      <origin rpy="0 0 0" xyz="0 0 0"/>
      <geometry>
        <mesh filename="../meshes/leg/front_hip_aa.stl" scale="0.001 0.001 0.001"/>
      </geometry>
    </visual>
    <collision>
      <origin rpy="0 0 0" xyz="0 0 0"/>
      <geometry>
        <mesh filename="../meshes/leg/front_hip_aa.stl" scale="0.001 0.001 0.001"/>
      </geometry>
    </collision>
  </link>
  <joint name="front_right_hip_aa_joint" type="fixed">
    <origin rpy="0 -0.7853981633974483 0" xyz="0.01 0.024 -0.1065"/>
    <parent link="front_spine_yaw_link"/>
    <child link="front_right_hip_aa_link"/>
  </joint>
  <link name="front_right_hip_fe_link">
    <inertial>
      <mass value="0.153185"/>
      <origin rpy="0 0 3.141592653589793" xyz="0.01808 0.004477 -0.011405"/>
      <inertia ixx="6.080E-05" ixy="3.521E-06" ixz="2.540E-06" iyy="1.052E-04" iyz="-1.247E-05" izz="7.157E-05"/>
    </inertial>
    <visual>
      <origin rpy="0 0 3.141592653589793" xyz="0 0 0"/>
      <geometry>
        <mesh filename="../meshes/leg/front_hip_fe.stl" scale="0.001 -0.001 0.001"/>
      </geometry>
    </visual>
    <collision>
      <origin rpy="0 0 3.141592653589793" xyz="0 0 0"/>
      <geometry>
        <mesh filename="../meshes/leg/front_hip_fe.stl" scale="0.001 -0.001 0.001"/>
      </geometry>
    </collision>
  </link>
  <joint name="front_right_hip_fe_joint" type="revolute">
    <origin rpy="0 0 0" xyz="0.083972 -0.0878 0"/>
    <axis xyz="1 0 0"/>
    <limit effort="2.43" lower="-0.7853981633974483" upper="0.17453292519943295" velocity="83.33333333333333"/>
    <dynamics damping="0.05" friction="0.1"/>
    <parent link="front_right_hip_aa_link"/>
    <child link="front_right_hip_fe_link"/>
  </joint>
  <transmission name="front_right_hip_fe_transmission">
    <type>transmission_interface/SimpleTransmission</type>
    <joint name="front_right_hip_fe_joint">
      <hardwareInterface>hardware_interface/EffortJointInterface</hardwareInterface>
    </joint>
    <actuator name="front_right_hip_fe_motor">
      <hardwareInterface>hardware_interface/EffortJointInterface</hardwareInterface>
      <mechanicalReduction>1</mechanicalReduction>
    </actuator>
  </transmission>
  <link name="front_right_upper_leg_link">
    <inertial>
      <mass value="0.158127"/>
      <origin rpy="0 0 -1.5707963267948966" xyz="0.0 -0.022563 -0.07012"/>
      <inertia ixx="2.824E-04" ixy="4.259E-09" ixz="-6.584E-08" iyy="2.882E-04" iyz="3.543E-05" izz="3.742E-05"/>
    </inertial>
    <visual>
      <origin rpy="0 0 -1.5707963267948966" xyz="0 0 0"/>
      <geometry>
        <mesh filename="../meshes/leg/front_upper_leg.stl" scale="0.001 0.001 0.001"/>
      </geometry>
    </visual>
    <collision>
      <origin rpy="0 0 -1.5707963267948966" xyz="0 0 0"/>
      <geometry>
        <mesh filename="../meshes/leg/front_upper_leg.stl" scale="0.001 0.001 0.001"/>
      </geometry>
    </collision>
  </link>
  <joint name="front_right_upper_leg_joint" type="revolute">
    <origin rpy="0 0.7853981633974483 0" xyz="0 -0.01415 0"/>
    <axis xyz="0 1 0"/>
    <limit effort="4.32" lower="-1.5707963267948966" upper="1.5707963267948966" velocity="46.875"/>
    <dynamics damping="0.05" friction="0.1"/>
    <parent link="front_right_hip_fe_link"/>
    <child link="front_right_upper_leg_link"/>
  </joint>
  <transmission name="front_right_upper_leg_transmission">
    <type>transmission_interface/SimpleTransmission</type>
    <joint name="front_right_upper_leg_joint">
      <hardwareInterface>hardware_interface/EffortJointInterface</hardwareInterface>
    </joint>
    <actuator name="front_right_upper_leg_motor">
      <hardwareInterface>hardware_interface/EffortJointInterface</hardwareInterface>
      <mechanicalReduction>1</mechanicalReduction>
    </actuator>
  </transmission>
  <link name="front_right_lower_leg_link">
    <inertial>
      <mass value="0.023961"/>
      <origin xyz="0 -0.00816 -0.044589"/>
      <inertia ixx="3.727E-05" ixy="-5.628E-16" ixz="2.285E-15" iyy="3.709E-05" iyz="5.027E-06" izz="1.815E-06"/>
    </inertial>
    <visual>
      <origin rpy="0 0 3.141592653589793" xyz="0 0 0"/>
      <geometry>
        <mesh filename="../meshes/leg/front_lower_leg.stl" scale="0.001 0.001 0.001"/>
      </geometry>
    </visual>
    <collision>
      <origin rpy="0 0 3.141592653589793" xyz="0 0 0"/>
      <geometry>
        <mesh filename="../meshes/leg/front_lower_leg.stl" scale="0.001 0.001 0.001"/>
      </geometry>
    </collision>
  </link>
  <joint name="front_right_lower_leg_joint" type="revolute">
    <axis xyz="0 1 0"/>
    <limit effort="4.32" lower="-1.5707963267948966" upper="1.5707963267948966" velocity="46.875"/>
    <dynamics damping="0.05" friction="0.1"/>
    <origin rpy="0 0 0" xyz="0 -0.0315 -0.1232"/>
    <parent link="front_right_upper_leg_link"/>
    <child link="front_right_lower_leg_link"/>
  </joint>
  <transmission name="front_right_lower_leg_transmission">
    <type>transmission_interface/SimpleTransmission</type>
    <joint name="front_right_lower_leg_joint">
      <hardwareInterface>hardware_interface/EffortJointInterface</hardwareInterface>
    </joint>
    <actuator name="front_right_lower_leg_motor">
      <hardwareInterface>hardware_interface/EffortJointInterface</hardwareInterface>
      <mechanicalReduction>1</mechanicalReduction>
    </actuator>
  </transmission>
  <link name="front_right_foot_contact_link">
    <inertial>
      <mass value="0.01"/>
      <origin xyz="0 0 0"/>
      <inertia ixx="1e-9" ixy="0.0" ixz="0.0" iyy="1e-9" iyz="0.0" izz="1e-9"/>
    </inertial>
    <visual>
      <origin xyz="0 0 0"/>
      <geometry>
        <sphere radius="0.015"/>
      </geometry>
    </visual>
    <collision>
      <origin xyz="0 0 0"/>
      <geometry>
        <sphere radius="0.015"/>
      </geometry>
    </collision>
  </link>
  <joint name="front_right_foot_contact_joint" type="fixed">
    <origin xyz="0 0 -0.105"/>
    <parent link="front_right_lower_leg_link"/>
    <child link="front_right_foot_contact_link"/>
  </joint>
  <link name="rear_left_hip_aa_link">
    <inertial>
      <mass value="0.149885"/>
      <origin xyz="-0.017329 -0.026389 0.014"/>
      <inertia ixx="2.575E-04" ixy="2.519E-05" ixz="7.023E-09" iyy="2.683E-05" iyz="-6.917E-08" izz="2.557E-04"/>
    </inertial>
    <visual>
      <origin rpy="0 0 0" xyz="0 0 0"/>
      <geometry>
        <mesh filename="../meshes/leg/front_hip_aa.stl" scale="0.001 0.001 0.001"/>
      </geometry>
    </visual>
    <collision>
      <origin rpy="0 0 0" xyz="0 0 0"/>
      <geometry>
        <mesh filename="../meshes/leg/front_hip_aa.stl" scale="0.001 0.001 0.001"/>
      </geometry>
    </collision>
  </link>
  <joint name="rear_left_hip_aa_joint" type="fixed">
    <origin rpy="0 0 3.141592653589793" xyz="-0.13424999999999998 -0.025 -0.02"/>
    <parent link="rear_spine_yaw_link"/>
    <child link="rear_left_hip_aa_link"/>
  </joint>
  <link name="rear_left_hip_fe_link">
    <inertial>
      <mass value="0.138767"/>
      <origin rpy="0 0 3.141592653589793" xyz="-0.01668 0.004473 -0.014463"/>
      <inertia ixx="6.067E-05" ixy="4.443E-06" ixz="-3.065E-06" iyy="1.026E-04" iyz="1.247E-05" izz="6.917E-05"/>
    </inertial>
    <visual>
      <origin rpy="0 0 3.141592653589793" xyz="0 0 -0.003"/>
      <geometry>
        <mesh filename="../meshes/leg/rear_hip_fe.stl" scale="-0.001 0.001 0.001"/>
      </geometry>
    </visual>
    <collision>
      <origin rpy="0 0 3.141592653589793" xyz="0 0 -0.003"/>
      <geometry>
        <mesh filename="../meshes/leg/rear_hip_fe.stl" scale="-0.001 0.001 0.001"/>
      </geometry>
    </collision>
  </link>
  <joint name="rear_left_hip_fe_joint" type="revolute">
    <origin rpy="0 0 3.141592653589793" xyz="-0.054678 -0.0878 0"/>
    <axis xyz="1 0 0"/>
    <limit effort="2.43" lower="-0.17453292519943295" upper="0.7853981633974483" velocity="83.33333333333333"/>
    <dynamics damping="0.05" friction="0.1"/>
    <parent link="rear_left_hip_aa_link"/>
    <child link="rear_left_hip_fe_link"/>
  </joint>
  <transmission name="rear_left_hip_fe_transmission">
    <type>transmission_interface/SimpleTransmission</type>
    <joint name="rear_left_hip_fe_joint">
      <hardwareInterface>hardware_interface/EffortJointInterface</hardwareInterface>
    </joint>
    <actuator name="rear_left_hip_fe_motor">
      <hardwareInterface>hardware_interface/EffortJointInterface</hardwareInterface>
      <mechanicalReduction>1</mechanicalReduction>
    </actuator>
  </transmission>
  <link name="rear_left_upper_leg_link">
    <inertial>
      <mass value="0.160653"/>
      <origin rpy="0 0 1.5707963267948966" xyz="0.0 0.02256 -0.07763"/>
      <inertia ixx="3.140E-04" ixy="6.009E-09" ixz="-7.395E-08" iyy="3.203E-04" iyz="3.738E-05" izz="3.808E-05"/>
    </inertial>
    <visual>
      <origin rpy="0 0 1.5707963267948966" xyz="0 0 0"/>
      <geometry>
        <mesh filename="../meshes/leg/rear_upper_leg.stl" scale="0.001 0.001 0.001"/>
      </geometry>
    </visual>
    <collision>
      <origin rpy="0 0 1.5707963267948966" xyz="0 0 0"/>
      <geometry>
        <mesh filename="../meshes/leg/rear_upper_leg.stl" scale="0.001 0.001 0.001"/>
      </geometry>
    </collision>
  </link>
  <joint name="rear_left_upper_leg_joint" type="revolute">
    <origin rpy="0 0 0" xyz="0 0.01415 0"/>
    <axis xyz="0 1 0"/>
    <limit effort="4.32" lower="-1.5707963267948966" upper="1.5707963267948966" velocity="46.875"/>
    <dynamics damping="0.05" friction="0.1"/>
    <parent link="rear_left_hip_fe_link"/>
    <child link="rear_left_upper_leg_link"/>
  </joint>
  <transmission name="rear_left_upper_leg_transmission">
    <type>transmission_interface/SimpleTransmission</type>
    <joint name="rear_left_upper_leg_joint">
      <hardwareInterface>hardware_interface/EffortJointInterface</hardwareInterface>
    </joint>
    <actuator name="rear_left_upper_leg_motor">
      <hardwareInterface>hardware_interface/EffortJointInterface</hardwareInterface>
      <mechanicalReduction>1</mechanicalReduction>
    </actuator>
  </transmission>
  <link name="rear_left_lower_leg_link">
    <inertial>
      <mass value="0.029071"/>
      <origin xyz="0 0.008801 -0.056722"/>
      <inertia ixx="6.791E-05" ixy="-1.480E-16" ixz="2.960E-15" iyy="6.774E-05" iyz="-7.319E-06" izz="2.092E-06"/>
    </inertial>
    <visual>
      <origin rpy="0 0 0" xyz="0 0 0"/>
      <geometry>
        <mesh filename="../meshes/leg/rear_lower_leg.stl" scale="0.001 0.001 0.001"/>
      </geometry>
    </visual>
    <collision>
      <origin rpy="0 0 0" xyz="0 0 0"/>
      <geometry>
        <mesh filename="../meshes/leg/rear_lower_leg.stl" scale="0.001 0.001 0.001"/>
      </geometry>
    </collision>
  </link>
  <joint name="rear_left_lower_leg_joint" type="revolute">
    <axis xyz="0 1 0"/>
    <limit effort="4.32" lower="-1.5707963267948966" upper="1.5707963267948966" velocity="46.875"/>
    <dynamics damping="0.05" friction="0.1"/>
    <origin rpy="0 0 0" xyz="0 0.0315 -0.134"/>
    <parent link="rear_left_upper_leg_link"/>
    <child link="rear_left_lower_leg_link"/>
  </joint>
  <transmission name="rear_left_lower_leg_transmission">
    <type>transmission_interface/SimpleTransmission</type>
    <joint name="rear_left_lower_leg_joint">
      <hardwareInterface>hardware_interface/EffortJointInterface</hardwareInterface>
    </joint>
    <actuator name="rear_left_lower_leg_motor">
      <hardwareInterface>hardware_interface/EffortJointInterface</hardwareInterface>
      <mechanicalReduction>1</mechanicalReduction>
    </actuator>
  </transmission>
  <link name="rear_left_foot_contact_link">
    <inertial>
      <mass value="0.01"/>
      <origin xyz="0 0 0"/>
      <inertia ixx="1e-9" ixy="0.0" ixz="0.0" iyy="1e-9" iyz="0.0" izz="1e-9"/>
    </inertial>
    <visual>
      <origin xyz="0 0 0"/>
      <geometry>
        <sphere radius="0.015"/>
      </geometry>
    </visual>
    <collision>
      <origin xyz="0 0 0"/>
      <geometry>
        <sphere radius="0.015"/>
      </geometry>
    </collision>
  </link>
  <joint name="rear_left_foot_contact_joint" type="fixed">
    <origin xyz="0 0 -0.135"/>
    <parent link="rear_left_lower_leg_link"/>
    <child link="rear_left_foot_contact_link"/>
  </joint>
  <link name="rear_right_hip_aa_link">
    <inertial>
      <mass value="0.149885"/>
      <origin xyz="-0.017329 -0.026389 0.014"/>
      <inertia ixx="2.575E-04" ixy="2.519E-05" ixz="7.023E-09" iyy="2.683E-05" iyz="-6.917E-08" izz="2.557E-04"/>
    </inertial>
    <visual>
      <origin rpy="0 0 0" xyz="0 0 0"/>
      <geometry>
        <mesh filename="../meshes/leg/front_hip_aa.stl" scale="0.001 0.001 0.001"/>
      </geometry>
    </visual>
    <collision>
      <origin rpy="0 0 0" xyz="0 0 0"/>
      <geometry>
        <mesh filename="../meshes/leg/front_hip_aa.stl" scale="0.001 0.001 0.001"/>
      </geometry>
    </collision>
  </link>
  <joint name="rear_right_hip_aa_joint" type="fixed">
    <origin rpy="0 0 0" xyz="-0.13424999999999998 0.025 -0.02"/>
    <parent link="rear_spine_yaw_link"/>
    <child link="rear_right_hip_aa_link"/>
  </joint>
  <link name="rear_right_hip_fe_link">
    <inertial>
      <mass value="0.138767"/>
      <origin rpy="0 0 0" xyz="0.01668 0.004473 -0.014463"/>
      <inertia ixx="6.067E-05" ixy="-4.443E-06" ixz="3.065E-06" iyy="1.026E-04" iyz="1.247E-05" izz="6.917E-05"/>
    </inertial>
    <visual>
      <origin rpy="0 0 0" xyz="0 0 -0.003"/>
      <geometry>
        <mesh filename="../meshes/leg/rear_hip_fe.stl" scale="0.001 0.001 0.001"/>
      </geometry>
    </visual>
    <collision>
      <origin rpy="0 0 0" xyz="0 0 -0.003"/>
      <geometry>
        <mesh filename="../meshes/leg/rear_hip_fe.stl" scale="0.001 0.001 0.001"/>
      </geometry>
    </collision>
  </link>
  <joint name="rear_right_hip_fe_joint" type="revolute">
    <origin rpy="0 0 0" xyz="0.054678 -0.0878 0"/>
    <axis xyz="1 0 0"/>
    <limit effort="2.43" lower="-0.7853981633974483" upper="0.17453292519943295" velocity="83.33333333333333"/>
    <dynamics damping="0.05" friction="0.1"/>
    <parent link="rear_right_hip_aa_link"/>
    <child link="rear_right_hip_fe_link"/>
  </joint>
  <transmission name="rear_right_hip_fe_transmission">
    <type>transmission_interface/SimpleTransmission</type>
    <joint name="rear_right_hip_fe_joint">
      <hardwareInterface>hardware_interface/EffortJointInterface</hardwareInterface>
    </joint>
    <actuator name="rear_right_hip_fe_motor">
      <hardwareInterface>hardware_interface/EffortJointInterface</hardwareInterface>
      <mechanicalReduction>1</mechanicalReduction>
    </actuator>
  </transmission>
  <link name="rear_right_upper_leg_link">
    <inertial>
      <mass value="0.160653"/>
      <origin rpy="0 0 -1.5707963267948966" xyz="0.0 -0.02256 -0.07763"/>
      <inertia ixx="3.140E-04" ixy="6.009E-09" ixz="-7.395E-08" iyy="3.203E-04" iyz="3.738E-05" izz="3.808E-05"/>
    </inertial>
    <visual>
      <origin rpy="0 0 -1.5707963267948966" xyz="0 0 0"/>
      <geometry>
        <mesh filename="../meshes/leg/rear_upper_leg.stl" scale="0.001 0.001 0.001"/>
      </geometry>
    </visual>
    <collision>
      <origin rpy="0 0 -1.5707963267948966" xyz="0 0 0"/>
      <geometry>
        <mesh filename="../meshes/leg/rear_upper_leg.stl" scale="0.001 0.001 0.001"/>
      </geometry>
    </collision>
  </link>
  <joint name="rear_right_upper_leg_joint" type="revolute">
    <origin rpy="0 0 0" xyz="0 -0.01415 0"/>
    <axis xyz="0 1 0"/>
    <limit effort="4.32" lower="-1.5707963267948966" upper="1.5707963267948966" velocity="46.875"/>
    <dynamics damping="0.05" friction="0.1"/>
    <parent link="rear_right_hip_fe_link"/>
    <child link="rear_right_upper_leg_link"/>
  </joint>
  <transmission name="rear_right_upper_leg_transmission">
    <type>transmission_interface/SimpleTransmission</type>
    <joint name="rear_right_upper_leg_joint">
      <hardwareInterface>hardware_interface/EffortJointInterface</hardwareInterface>
    </joint>
    <actuator name="rear_right_upper_leg_motor">
      <hardwareInterface>hardware_interface/EffortJointInterface</hardwareInterface>
      <mechanicalReduction>1</mechanicalReduction>
    </actuator>
  </transmission>
  <link name="rear_right_lower_leg_link">
    <inertial>
      <mass value="0.029071"/>
      <origin xyz="0 -0.008801 -0.056722"/>
      <inertia ixx="6.791E-05" ixy="-1.480E-16" ixz="2.960E-15" iyy="6.774E-05" iyz="7.319E-06" izz="2.092E-06"/>
    </inertial>
    <visual>
      <origin rpy="0 0 3.141592653589793" xyz="0 0 0"/>
      <geometry>
        <mesh filename="../meshes/leg/rear_lower_leg.stl" scale="0.001 0.001 0.001"/>
      </geometry>
    </visual>
    <collision>
      <origin rpy="0 0 3.141592653589793" xyz="0 0 0"/>
      <geometry>
        <mesh filename="../meshes/leg/rear_lower_leg.stl" scale="0.001 0.001 0.001"/>
      </geometry>
    </collision>
  </link>
  <joint name="rear_right_lower_leg_joint" type="revolute">
    <axis xyz="0 1 0"/>
    <limit effort="4.32" lower="-1.5707963267948966" upper="1.5707963267948966" velocity="46.875"/>
    <dynamics damping="0.05" friction="0.1"/>
    <origin rpy="0 0 0" xyz="0 -0.0315 -0.134"/>
    <parent link="rear_right_upper_leg_link"/>
    <child link="rear_right_lower_leg_link"/>
  </joint>
  <transmission name="rear_right_lower_leg_transmission">
    <type>transmission_interface/SimpleTransmission</type>
    <joint name="rear_right_lower_leg_joint">
      <hardwareInterface>hardware_interface/EffortJointInterface</hardwareInterface>
    </joint>
    <actuator name="rear_right_lower_leg_motor">
      <hardwareInterface>hardware_interface/EffortJointInterface</hardwareInterface>
      <mechanicalReduction>1</mechanicalReduction>
    </actuator>
  </transmission>
  <link name="rear_right_foot_contact_link">
    <inertial>
      <mass value="0.01"/>
      <origin xyz="0 0 0"/>
      <inertia ixx="1e-9" ixy="0.0" ixz="0.0" iyy="1e-9" iyz="0.0" izz="1e-9"/>
    </inertial>
    <visual>
      <origin xyz="0 0 0"/>
      <geometry>
        <sphere radius="0.015"/>
      </geometry>
    </visual>
    <collision>
      <origin xyz="0 0 0"/>
      <geometry>
        <sphere radius="0.015"/>
      </geometry>
    </collision>
  </link>
  <joint name="rear_right_foot_contact_joint" type="fixed">
    <origin xyz="0 0 -0.135"/>
    <parent link="rear_right_lower_leg_link"/>
    <child link="rear_right_foot_contact_link"/>
  </joint>
  <!--<xacro:neck/>-->
  <!--<xacro:head/>-->
</robot>

