<?xml version="1.0" ?>
<!-- =================================================================================== -->
<!-- |    This document was autogenerated by xacro from urdf/ester.urdf.xacro          | -->
<!-- |    EDITING THIS FILE BY HAND IS NOT RECOMMENDED                                 | -->
<!-- =================================================================================== -->
<robot name="ester">
  <gazebo>
    <plugin filename="libgazebo_ros_control.so" name="gazebo_ros_control">
      <robotNamespace>/ester</robotNamespace>
    </plugin>
    <selfCollide>false</selfCollide>
  </gazebo>
  <!-- Dummy parent link for Gazebo -->
  <link name="base_link"/>
  <link name="spine_center_link">
    <inertial>
      <mass value="2.284352"/>
      <origin xyz="0.000343 -0.000121 -0.042803"/>
      <inertia ixx="5.168E-04" ixy="-7.248E-05" ixz="4.269E-06" iyy="3.674E-04" iyz="-4.881E-06" izz="5.638E-04"/>
    </inertial>
    <visual>
      <origin rpy="0 0 0" xyz="0 0 0"/>
      <geometry>
        <mesh filename="../meshes/spine/spine_center.stl" scale="0.001 0.001 0.001"/>
      </geometry>
    </visual>
    <collision>
      <origin rpy="0 0 0" xyz="0 0 0"/>
      <geometry>
        <mesh filename="../meshes/spine/spine_center.stl" scale="0.001 0.001 0.001"/>
      </geometry>
    </collision>
  </link>
  <joint name="spine_center_joint" type="fixed">
    <origin rpy="0 0 0" xyz="0 0 0"/>
    <parent link="base_link"/>
    <child link="spine_center_link"/>
  </joint>
  <link name="front_spine_pitch_link">
    <inertial>
      <mass value="0.153731"/>
      <origin xyz="-0.00289 -0.024746 -0.007461"/>
      <inertia ixx="5.225E-05" ixy="5.714E-08" ixz="3.625E-06" iyy="8.599E-05" iyz="-1.177E-07" izz="6.755E-05"/>
    </inertial>
    <visual>
      <origin xyz="0 0 0"/>
      <geometry>
        <mesh filename="../meshes/spine/front_spine_pitch.stl" scale="0.001 0.001 0.001"/>
      </geometry>
    </visual>
    <collision>
      <origin xyz="0 0 0"/>
      <geometry>
        <mesh filename="../meshes/spine/front_spine_pitch.stl" scale="0.001 0.001 0.001"/>
      </geometry>
    </collision>
  </link>
  <joint name="front_spine_pitch_joint" type="revolute">
    <origin rpy="0 0 0" xyz="0.045 0.025 -0.015"/>
    <axis xyz="0 1 0"/>
    <limit effort="2.5" lower="-0.2617993877991494" upper="0.2617993877991494" velocity="83.775"/>
    <dynamics damping="0.05" friction="0.1"/>
    <parent link="spine_center_link"/>
    <child link="front_spine_pitch_link"/>
  </joint>
  <transmission name="front_spine_pitch_transmission">
    <type>transmission_interface/SimpleTransmission</type>
    <joint name="front_spine_pitch_joint">
      <hardwareInterface>hardware_interface/EffortJointInterface</hardwareInterface>
    </joint>
    <actuator name="front_spine_pitch_motor">
      <hardwareInterface>hardware_interface/EffortJointInterface</hardwareInterface>
      <mechanicalReduction>1</mechanicalReduction>
    </actuator>
  </transmission>
  <link name="rear_spine_pitch_link">
    <inertial>
      <mass value="0.153731"/>
      <origin xyz="-0.00289 0.024762 -0.007461"/>
      <inertia ixx="5.225E-05" ixy="-5.718E-08" ixz="3.625E-06" iyy="8.599E-05" iyz="1.178E-07" izz="6.755E-05"/>
    </inertial>
    <visual>
      <origin xyz="0 0 0"/>
      <geometry>
        <mesh filename="../meshes/spine/rear_spine_pitch.stl" scale="0.001 0.001 0.001"/>
      </geometry>
    </visual>
    <collision>
      <origin xyz="0 0 0"/>
      <geometry>
        <mesh filename="../meshes/spine/rear_spine_pitch.stl" scale="0.001 0.001 0.001"/>
      </geometry>
    </collision>
  </link>
  <joint name="rear_spine_pitch_joint" type="revolute">
    <origin rpy="0 0 0" xyz="-0.045 -0.025 -0.015"/>
    <axis xyz="0 1 0"/>
    <limit effort="2.5" lower="-0.2617993877991494" upper="0.2617993877991494" velocity="83.775"/>
    <dynamics damping="0.05" friction="0.1"/>
    <parent link="spine_center_link"/>
    <child link="rear_spine_pitch_link"/>
  </joint>
  <transmission name="rear_spine_pitch_transmission">
    <type>transmission_interface/SimpleTransmission</type>
    <joint name="rear_spine_pitch_joint">
      <hardwareInterface>hardware_interface/EffortJointInterface</hardwareInterface>
    </joint>
    <actuator name="rear_spine_pitch_motor">
      <hardwareInterface>hardware_interface/EffortJointInterface</hardwareInterface>
      <mechanicalReduction>1</mechanicalReduction>
    </actuator>
  </transmission>
  <link name="front_spine_yaw_link">
    <inertial>
      <mass value="0.1"/>
      <origin xyz="0 0 0"/>
      <inertia ixx="1E-05" ixy="0" ixz="0" iyy="1E-05" iyz="0" izz="1E-05"/>
    </inertial>
  </link>
  <joint name="front_spine_yaw_joint" type="revolute">
    <origin rpy="0 0 0" xyz="0 -0.02505 0.02115"/>
    <axis xyz="0 0 1"/>
    <limit effort="2.5" lower="-0.2617993877991494" upper="0.2617993877991494" velocity="83.775"/>
    <dynamics damping="0.05" friction="0.1"/>
    <parent link="front_spine_pitch_link"/>
    <child link="front_spine_yaw_link"/>
  </joint>
  <transmission name="front_spine_yaw_transmission">
    <type>transmission_interface/SimpleTransmission</type>
    <joint name="front_spine_yaw_joint">
      <hardwareInterface>hardware_interface/EffortJointInterface</hardwareInterface>
    </joint>
    <actuator name="front_spine_yaw_motor">
      <hardwareInterface>hardware_interface/EffortJointInterface</hardwareInterface>
      <mechanicalReduction>1</mechanicalReduction>
    </actuator>
  </transmission>
  <link name="rear_spine_yaw_link">
    <inertial>
      <mass value="0.1"/>
      <origin xyz="0 0 0"/>
      <inertia ixx="1E-05" ixy="0" ixz="0" iyy="1E-05" iyz="0" izz="1E-05"/>
    </inertial>
  </link>
  <joint name="rear_spine_yaw_joint" type="revolute">
    <origin rpy="0 0 0" xyz="0 0.02505 0.02115"/>
    <axis xyz="0 0 1"/>
    <limit effort="2.5" lower="-0.2617993877991494" upper="0.2617993877991494" velocity="83.775"/>
    <dynamics damping="0.05" friction="0.1"/>
    <parent link="rear_spine_pitch_link"/>
    <child link="rear_spine_yaw_link"/>
  </joint>
  <transmission name="rear_spine_yaw_transmission">
    <type>transmission_interface/SimpleTransmission</type>
    <joint name="rear_spine_yaw_joint">
      <hardwareInterface>hardware_interface/EffortJointInterface</hardwareInterface>
    </joint>
    <actuator name="rear_spine_yaw_motor">
      <hardwareInterface>hardware_interface/EffortJointInterface</hardwareInterface>
      <mechanicalReduction>1</mechanicalReduction>
    </actuator>
  </transmission>
  <link name="front_left_hip_aa_link">
    <inertial>
      <mass value="0.149885"/>
      <origin xyz="-0.017329 -0.026389 0.014"/>
      <inertia ixx="2.575E-04" ixy="2.519E-05" ixz="7.023E-09" iyy="2.683E-05" iyz="-6.917E-08" izz="2.557E-04"/>
    </inertial>
    <visual>
      <origin rpy="0 0 0" xyz="0 0 0"/>
      <geometry>
        <mesh filename="../meshes/leg/front_hip_aa.stl" scale="0.001 0.001 0.001"/>
      </geometry>
    </visual>
    <collision>
      <origin rpy="0 0 0" xyz="0 0 0"/>
      <geometry>
        <mesh filename="../meshes/leg/front_hip_aa.stl" scale="0.001 0.001 0.001"/>
      </geometry>
    </collision>
  </link>
  <joint name="front_left_hip_aa_joint" type="fixed">
    <origin rpy="0 0.3490658503988659 3.141592653589793" xyz="-0.0178 -0.024 -0.1065"/>
    <parent link="front_spine_yaw_link"/>
    <child link="front_left_hip_aa_link"/>
  </joint>
  <link name="front_left_hip_fe_link">
    <inertial>
      <mass value="0.153186"/>
      <origin xyz="-0.061937 0.003088 -0.021037"/>
      <inertia ixx="7.863E-05" ixy="-2.900E-06" ixz="-8.186E-06" iyy="1.242E-04" iyz="9.777E-06" izz="7.027E-05"/>
    </inertial>
    <visual>
      <origin rpy="0 0 0" xyz="0 0 0"/>
      <geometry>
        <mesh filename="../meshes/leg/front_left_hip_fe.stl" scale="0.001 0.001 0.001"/>
      </geometry>
    </visual>
    <collision>
      <origin rpy="0 0 0" xyz="0 0 0"/>
      <geometry>
        <mesh filename="../meshes/leg/front_left_hip_fe.stl" scale="0.001 0.001 0.001"/>
      </geometry>
    </collision>
  </link>
  <joint name="front_left_hip_fe_joint" type="revolute">
    <origin rpy="0 0 0" xyz="-0.0175 -0.0878 0"/>
    <axis xyz="1 0 0"/>
    <limit effort="2.5" lower="-0.7853981633974483" upper="0.17453292519943295" velocity="83.775"/>
    <dynamics damping="0.05" friction="0.1"/>
    <parent link="front_left_hip_aa_link"/>
    <child link="front_left_hip_fe_link"/>
  </joint>
  <transmission name="front_left_hip_fe_transmission">
    <type>transmission_interface/SimpleTransmission</type>
    <joint name="front_left_hip_fe_joint">
      <hardwareInterface>hardware_interface/EffortJointInterface</hardwareInterface>
    </joint>
    <actuator name="front_left_hip_fe_motor">
      <hardwareInterface>hardware_interface/EffortJointInterface</hardwareInterface>
      <mechanicalReduction>1</mechanicalReduction>
    </actuator>
  </transmission>
  <link name="front_left_upper_leg_link">
    <inertial>
      <mass value="0.154958"/>
      <origin xyz="0.000013 0.020573 -0.065721"/>
      <inertia ixx="2.379E-04" ixy="6.564E-09" ixz="-5.075E-08" iyy="2.382E-04" iyz="2.772E-05" izz="2.819E-05"/>
    </inertial>
    <visual>
      <origin rpy="0 0 0" xyz="0 0 0"/>
      <geometry>
        <mesh filename="../meshes/leg/front_left_upper_leg.stl" scale="0.001 0.001 0.001"/>
      </geometry>
    </visual>
    <collision>
      <origin rpy="0 0 0" xyz="0 0 0"/>
      <geometry>
        <mesh filename="../meshes/leg/front_left_upper_leg.stl" scale="0.001 0.001 0.001"/>
      </geometry>
    </collision>
  </link>
  <joint name="front_left_upper_leg_joint" type="revolute">
    <origin rpy="0 0.3490658503988659 3.141592653589793" xyz="-0.0773 -0.013 0"/>
    <axis xyz="0 1 0"/>
    <limit effort="2.5" lower="-1.5707963267948966" upper="1.5707963267948966" velocity="83.775"/>
    <dynamics damping="0.05" friction="0.1"/>
    <parent link="front_left_hip_fe_link"/>
    <child link="front_left_upper_leg_link"/>
  </joint>
  <transmission name="front_left_upper_leg_transmission">
    <type>transmission_interface/SimpleTransmission</type>
    <joint name="front_left_upper_leg_joint">
      <hardwareInterface>hardware_interface/EffortJointInterface</hardwareInterface>
    </joint>
    <actuator name="front_left_upper_leg_motor">
      <hardwareInterface>hardware_interface/EffortJointInterface</hardwareInterface>
      <mechanicalReduction>1</mechanicalReduction>
    </actuator>
  </transmission>
  <link name="front_left_lower_leg_link">
    <inertial>
      <mass value="0.023609"/>
      <origin xyz="0 -0.00816 -0.044589"/>
      <inertia ixx="3.673E-05" ixy="-1.666E-16" ixz="6.558E-16" iyy="3.653E-05" iyz="-5.092E-06" izz="1.804E-06"/>
    </inertial>
    <visual>
      <origin rpy="0 0 0" xyz="0 0 0"/>
      <geometry>
        <mesh filename="../meshes/leg/front_lower_leg.stl" scale="0.001 0.001 0.001"/>
      </geometry>
    </visual>
    <collision>
      <origin rpy="0 0 0" xyz="0 0 0"/>
      <geometry>
        <mesh filename="../meshes/leg/front_lower_leg.stl" scale="0.001 0.001 0.001"/>
      </geometry>
    </collision>
  </link>
  <joint name="front_left_lower_leg_joint" type="revolute">
    <axis xyz="0 1 0"/>
    <limit effort="2.5" lower="-1.5707963267948966" upper="1.5707963267948966" velocity="83.775"/>
    <dynamics damping="0.05" friction="0.1"/>
    <origin rpy="0 0 0" xyz="0 0.0285 -0.1232"/>
    <parent link="front_left_upper_leg_link"/>
    <child link="front_left_lower_leg_link"/>
  </joint>
  <transmission name="front_left_lower_leg_transmission">
    <type>transmission_interface/SimpleTransmission</type>
    <joint name="front_left_lower_leg_joint">
      <hardwareInterface>hardware_interface/EffortJointInterface</hardwareInterface>
    </joint>
    <actuator name="front_left_lower_leg_motor">
      <hardwareInterface>hardware_interface/EffortJointInterface</hardwareInterface>
      <mechanicalReduction>1</mechanicalReduction>
    </actuator>
  </transmission>
  <link name="front_left_foot_contact_link">
    <inertial>
      <mass value="0.01"/>
      <origin xyz="0 0 0"/>
      <inertia ixx="1e-9" ixy="0.0" ixz="0.0" iyy="1e-9" iyz="0.0" izz="1e-9"/>
    </inertial>
    <visual>
      <origin xyz="0 0 0"/>
      <geometry>
        <sphere radius="0.015"/>
      </geometry>
    </visual>
    <collision>
      <origin xyz="0 0 0"/>
      <geometry>
        <sphere radius="0.015"/>
      </geometry>
    </collision>
  </link>
  <joint name="front_left_foot_contact_joint" type="fixed">
    <origin xyz="0 0 -0.105"/>
    <parent link="front_left_lower_leg_link"/>
    <child link="front_left_foot_contact_link"/>
  </joint>
  <link name="front_right_hip_aa_link">
    <inertial>
      <mass value="0.149885"/>
      <origin xyz="-0.017329 -0.026389 0.014"/>
      <inertia ixx="2.575E-04" ixy="2.519E-05" ixz="7.023E-09" iyy="2.683E-05" iyz="-6.917E-08" izz="2.557E-04"/>
    </inertial>
    <visual>
      <origin rpy="0 0 0" xyz="0 0 0"/>
      <geometry>
        <mesh filename="../meshes/leg/front_hip_aa.stl" scale="0.001 0.001 0.001"/>
      </geometry>
    </visual>
    <collision>
      <origin rpy="0 0 0" xyz="0 0 0"/>
      <geometry>
        <mesh filename="../meshes/leg/front_hip_aa.stl" scale="0.001 0.001 0.001"/>
      </geometry>
    </collision>
  </link>
  <joint name="front_right_hip_aa_joint" type="fixed">
    <origin rpy="0 -0.3490658503988659 0" xyz="-0.0178 0.024 -0.1065"/>
    <parent link="front_spine_yaw_link"/>
    <child link="front_right_hip_aa_link"/>
  </joint>
  <link name="front_right_hip_fe_link">
    <inertial>
      <mass value="0.153185"/>
      <origin xyz="-0.061937 -0.003088 -0.021037"/>
      <inertia ixx="7.863E-05" ixy="2.900E-06" ixz="-8.186E-06" iyy="1.242E-04" iyz="-9.776E-06" izz="7.027E-05"/>
    </inertial>
    <visual>
      <origin rpy="0 0 0" xyz="0 0 0"/>
      <geometry>
        <mesh filename="../meshes/leg/front_right_hip_fe.stl" scale="0.001 0.001 0.001"/>
      </geometry>
    </visual>
    <collision>
      <origin rpy="0 0 0" xyz="0 0 0"/>
      <geometry>
        <mesh filename="../meshes/leg/front_right_hip_fe.stl" scale="0.001 0.001 0.001"/>
      </geometry>
    </collision>
  </link>
  <joint name="front_right_hip_fe_joint" type="revolute">
    <origin rpy="0 0 3.141592653589793" xyz="0.0135 -0.0878 0"/>
    <axis xyz="1 0 0"/>
    <limit effort="2.5" lower="-0.17453292519943295" upper="0.7853981633974483" velocity="83.775"/>
    <dynamics damping="0.05" friction="0.1"/>
    <parent link="front_right_hip_aa_link"/>
    <child link="front_right_hip_fe_link"/>
  </joint>
  <transmission name="front_right_hip_fe_transmission">
    <type>transmission_interface/SimpleTransmission</type>
    <joint name="front_right_hip_fe_joint">
      <hardwareInterface>hardware_interface/EffortJointInterface</hardwareInterface>
    </joint>
    <actuator name="front_right_hip_fe_motor">
      <hardwareInterface>hardware_interface/EffortJointInterface</hardwareInterface>
      <mechanicalReduction>1</mechanicalReduction>
    </actuator>
  </transmission>
  <link name="front_right_upper_leg_link">
    <inertial>
      <mass value="0.154958"/>
      <origin xyz="0.000013 -0.020573 -0.065721"/>
      <inertia ixx="2.379E-04" ixy="6.564E-09" ixz="5.075E-08" iyy="2.382E-04" iyz="-2.772E-05" izz="2.819E-05"/>
    </inertial>
    <visual>
      <origin rpy="0 0 0" xyz="0 0 0"/>
      <geometry>
        <mesh filename="../meshes/leg/front_right_upper_leg.stl" scale="0.001 0.001 0.001"/>
      </geometry>
    </visual>
    <collision>
      <origin rpy="0 0 0" xyz="0 0 0"/>
      <geometry>
        <mesh filename="../meshes/leg/front_right_upper_leg.stl" scale="0.001 0.001 0.001"/>
      </geometry>
    </collision>
  </link>
  <joint name="front_right_upper_leg_joint" type="revolute">
    <origin rpy="0 0.3490658503988659 3.141592653589793" xyz="-0.0773 0.013 0"/>
    <axis xyz="0 1 0"/>
    <limit effort="2.5" lower="-1.5707963267948966" upper="1.5707963267948966" velocity="83.775"/>
    <dynamics damping="0.05" friction="0.1"/>
    <parent link="front_right_hip_fe_link"/>
    <child link="front_right_upper_leg_link"/>
  </joint>
  <transmission name="front_right_upper_leg_transmission">
    <type>transmission_interface/SimpleTransmission</type>
    <joint name="front_right_upper_leg_joint">
      <hardwareInterface>hardware_interface/EffortJointInterface</hardwareInterface>
    </joint>
    <actuator name="front_right_upper_leg_motor">
      <hardwareInterface>hardware_interface/EffortJointInterface</hardwareInterface>
      <mechanicalReduction>1</mechanicalReduction>
    </actuator>
  </transmission>
  <link name="front_right_lower_leg_link">
    <inertial>
      <mass value="0.023609"/>
      <origin xyz="0 -0.00816 -0.044589"/>
      <inertia ixx="3.673E-05" ixy="-1.369E-16" ixz="5.901E-16" iyy="3.653E-05" iyz="5.092E-06" izz="1.804E-06"/>
    </inertial>
    <visual>
      <origin rpy="0 0 3.141592653589793" xyz="0 0 0"/>
      <geometry>
        <mesh filename="../meshes/leg/front_lower_leg.stl" scale="0.001 0.001 0.001"/>
      </geometry>
    </visual>
    <collision>
      <origin rpy="0 0 3.141592653589793" xyz="0 0 0"/>
      <geometry>
        <mesh filename="../meshes/leg/front_lower_leg.stl" scale="0.001 0.001 0.001"/>
      </geometry>
    </collision>
  </link>
  <joint name="front_right_lower_leg_joint" type="revolute">
    <axis xyz="0 1 0"/>
    <limit effort="2.5" lower="-1.5707963267948966" upper="1.5707963267948966" velocity="83.775"/>
    <dynamics damping="0.05" friction="0.1"/>
    <origin rpy="0 0 0" xyz="0 -0.0285 -0.1232"/>
    <parent link="front_right_upper_leg_link"/>
    <child link="front_right_lower_leg_link"/>
  </joint>
  <transmission name="front_right_lower_leg_transmission">
    <type>transmission_interface/SimpleTransmission</type>
    <joint name="front_right_lower_leg_joint">
      <hardwareInterface>hardware_interface/EffortJointInterface</hardwareInterface>
    </joint>
    <actuator name="front_right_lower_leg_motor">
      <hardwareInterface>hardware_interface/EffortJointInterface</hardwareInterface>
      <mechanicalReduction>1</mechanicalReduction>
    </actuator>
  </transmission>
  <link name="front_right_foot_contact_link">
    <inertial>
      <mass value="0.01"/>
      <origin xyz="0 0 0"/>
      <inertia ixx="1e-9" ixy="0.0" ixz="0.0" iyy="1e-9" iyz="0.0" izz="1e-9"/>
    </inertial>
    <visual>
      <origin xyz="0 0 0"/>
      <geometry>
        <sphere radius="0.015"/>
      </geometry>
    </visual>
    <collision>
      <origin xyz="0 0 0"/>
      <geometry>
        <sphere radius="0.015"/>
      </geometry>
    </collision>
  </link>
  <joint name="front_right_foot_contact_joint" type="fixed">
    <origin xyz="0 0 -0.105"/>
    <parent link="front_right_lower_leg_link"/>
    <child link="front_right_foot_contact_link"/>
  </joint>
  <link name="rear_left_hip_aa_link">
    <inertial>
      <mass value="0.149885"/>
      <origin xyz="-0.017329 -0.026389 0.014"/>
      <inertia ixx="2.575E-04" ixy="2.519E-05" ixz="7.023E-09" iyy="2.683E-05" iyz="-6.917E-08" izz="2.557E-04"/>
    </inertial>
    <visual>
      <origin rpy="0 0 0" xyz="0 0 0"/>
      <geometry>
        <mesh filename="../meshes/leg/front_hip_aa.stl" scale="0.001 0.001 0.001"/>
      </geometry>
    </visual>
    <collision>
      <origin rpy="0 0 0" xyz="0 0 0"/>
      <geometry>
        <mesh filename="../meshes/leg/front_hip_aa.stl" scale="0.001 0.001 0.001"/>
      </geometry>
    </collision>
  </link>
  <joint name="rear_left_hip_aa_joint" type="fixed">
    <origin rpy="0 0 3.141592653589793" xyz="-0.10425 -0.025 -0.02"/>
    <parent link="rear_spine_yaw_link"/>
    <child link="rear_left_hip_aa_link"/>
  </joint>
  <link name="rear_left_hip_fe_link">
    <inertial>
      <mass value="0.153223"/>
      <origin xyz="0.039662 -0.003149 -0.021034"/>
      <inertia ixx="7.862E-05" ixy="3.822E-06" ixz="-3.028E-06" iyy="1.188E-04" iyz="-9.665E-06" izz="6.484E-05"/>
    </inertial>
    <visual>
      <origin rpy="0 0 3.141592653589793" xyz="0 0 0"/>
      <geometry>
        <mesh filename="../meshes/leg/rear_right_hip_fe.stl" scale="0.001 0.001 0.001"/>
      </geometry>
    </visual>
    <collision>
      <origin rpy="0 0 3.141592653589793" xyz="0 0 0"/>
      <geometry>
        <mesh filename="../meshes/leg/rear_right_hip_fe.stl" scale="0.001 0.001 0.001"/>
      </geometry>
    </collision>
  </link>
  <joint name="rear_left_hip_fe_joint" type="revolute">
    <origin rpy="0 0 0" xyz="-0.0175 -0.0878 0"/>
    <axis xyz="1 0 0"/>
    <limit effort="2.5" lower="-0.7853981633974483" upper="0.17453292519943295" velocity="83.775"/>
    <dynamics damping="0.05" friction="0.1"/>
    <parent link="rear_left_hip_aa_link"/>
    <child link="rear_left_hip_fe_link"/>
  </joint>
  <transmission name="rear_left_hip_fe_transmission">
    <type>transmission_interface/SimpleTransmission</type>
    <joint name="rear_left_hip_fe_joint">
      <hardwareInterface>hardware_interface/EffortJointInterface</hardwareInterface>
    </joint>
    <actuator name="rear_left_hip_fe_motor">
      <hardwareInterface>hardware_interface/EffortJointInterface</hardwareInterface>
      <mechanicalReduction>1</mechanicalReduction>
    </actuator>
  </transmission>
  <link name="rear_left_upper_leg_link">
    <inertial>
      <mass value="0.160729"/>
      <origin xyz="0.000013 0.0287 -0.069823"/>
      <inertia ixx="2.980E-04" ixy="6.814E-09" ixz="5.850E-08" iyy="2.986E-04" iyz="3.241E-05" izz="2.929E-05"/>
    </inertial>
    <visual>
      <origin rpy="0 0 0" xyz="0 0 0"/>
      <geometry>
        <mesh filename="../meshes/leg/rear_left_upper_leg.stl" scale="0.001 0.001 0.001"/>
      </geometry>
    </visual>
    <collision>
      <origin rpy="0 0 0" xyz="0 0 0"/>
      <geometry>
        <mesh filename="../meshes/leg/rear_left_upper_leg.stl" scale="0.001 0.001 0.001"/>
      </geometry>
    </collision>
  </link>
  <joint name="rear_left_upper_leg_joint" type="revolute">
    <origin rpy="0 0 3.141592653589793" xyz="-0.0259 -0.013 0"/>
    <axis xyz="0 1 0"/>
    <limit effort="2.5" lower="-1.5707963267948966" upper="1.5707963267948966" velocity="83.775"/>
    <dynamics damping="0.05" friction="0.1"/>
    <parent link="rear_left_hip_fe_link"/>
    <child link="rear_left_upper_leg_link"/>
  </joint>
  <transmission name="rear_left_upper_leg_transmission">
    <type>transmission_interface/SimpleTransmission</type>
    <joint name="rear_left_upper_leg_joint">
      <hardwareInterface>hardware_interface/EffortJointInterface</hardwareInterface>
    </joint>
    <actuator name="rear_left_upper_leg_motor">
      <hardwareInterface>hardware_interface/EffortJointInterface</hardwareInterface>
      <mechanicalReduction>1</mechanicalReduction>
    </actuator>
  </transmission>
  <link name="rear_left_lower_leg_link">
    <inertial>
      <mass value="0.028708"/>
      <origin xyz="0 0.008269 -0.057302"/>
      <inertia ixx="6.697E-05" ixy="-6.929E-17" ixz="3.012E-16" iyy="6.678E-05" iyz="-7.390E-06" izz="2.0798E-06"/>
    </inertial>
    <visual>
      <origin rpy="0 0 0" xyz="0 0 0"/>
      <geometry>
        <mesh filename="../meshes/leg/rear_lower_leg.stl" scale="0.001 0.001 0.001"/>
      </geometry>
    </visual>
    <collision>
      <origin rpy="0 0 0" xyz="0 0 0"/>
      <geometry>
        <mesh filename="../meshes/leg/rear_lower_leg.stl" scale="0.001 0.001 0.001"/>
      </geometry>
    </collision>
  </link>
  <joint name="rear_left_lower_leg_joint" type="revolute">
    <axis xyz="0 1 0"/>
    <limit effort="2.5" lower="-1.5707963267948966" upper="1.5707963267948966" velocity="83.775"/>
    <dynamics damping="0.05" friction="0.1"/>
    <origin rpy="0 0 0" xyz="0 0.0285 -0.134"/>
    <parent link="rear_left_upper_leg_link"/>
    <child link="rear_left_lower_leg_link"/>
  </joint>
  <transmission name="rear_left_lower_leg_transmission">
    <type>transmission_interface/SimpleTransmission</type>
    <joint name="rear_left_lower_leg_joint">
      <hardwareInterface>hardware_interface/EffortJointInterface</hardwareInterface>
    </joint>
    <actuator name="rear_left_lower_leg_motor">
      <hardwareInterface>hardware_interface/EffortJointInterface</hardwareInterface>
      <mechanicalReduction>1</mechanicalReduction>
    </actuator>
  </transmission>
  <link name="rear_left_foot_contact_link">
    <inertial>
      <mass value="0.01"/>
      <origin xyz="0 0 0"/>
      <inertia ixx="1e-9" ixy="0.0" ixz="0.0" iyy="1e-9" iyz="0.0" izz="1e-9"/>
    </inertial>
    <visual>
      <origin xyz="0 0 0"/>
      <geometry>
        <sphere radius="0.015"/>
      </geometry>
    </visual>
    <collision>
      <origin xyz="0 0 0"/>
      <geometry>
        <sphere radius="0.015"/>
      </geometry>
    </collision>
  </link>
  <joint name="rear_left_foot_contact_joint" type="fixed">
    <origin xyz="0 0 -0.135"/>
    <parent link="rear_left_lower_leg_link"/>
    <child link="rear_left_foot_contact_link"/>
  </joint>
  <link name="rear_right_hip_aa_link">
    <inertial>
      <mass value="0.149885"/>
      <origin xyz="-0.017329 -0.026389 0.014"/>
      <inertia ixx="2.575E-04" ixy="2.519E-05" ixz="7.023E-09" iyy="2.683E-05" iyz="-6.917E-08" izz="2.557E-04"/>
    </inertial>
    <visual>
      <origin rpy="0 0 0" xyz="0 0 0"/>
      <geometry>
        <mesh filename="../meshes/leg/front_hip_aa.stl" scale="0.001 0.001 0.001"/>
      </geometry>
    </visual>
    <collision>
      <origin rpy="0 0 0" xyz="0 0 0"/>
      <geometry>
        <mesh filename="../meshes/leg/front_hip_aa.stl" scale="0.001 0.001 0.001"/>
      </geometry>
    </collision>
  </link>
  <joint name="rear_right_hip_aa_joint" type="fixed">
    <origin rpy="0 0 0" xyz="-0.10425 0.025 -0.02"/>
    <parent link="rear_spine_yaw_link"/>
    <child link="rear_right_hip_aa_link"/>
  </joint>
  <link name="rear_right_hip_fe_link">
    <inertial>
      <mass value="0.158428"/>
      <origin xyz="0.038077 0.003046 -0.020343"/>
      <inertia ixx="8.134E-05" ixy="-4.587E-06" ixz="2.081E-06" iyy="1.332E-04" iyz="9.999E-06" izz="7.691E-05"/>
    </inertial>
    <visual>
      <origin rpy="0 0 3.141592653589793" xyz="0 0 0"/>
      <geometry>
        <mesh filename="../meshes/leg/rear_left_hip_fe.stl" scale="0.001 0.001 0.001"/>
      </geometry>
    </visual>
    <collision>
      <origin rpy="0 0 3.141592653589793" xyz="0 0 0"/>
      <geometry>
        <mesh filename="../meshes/leg/rear_left_hip_fe.stl" scale="0.001 0.001 0.001"/>
      </geometry>
    </collision>
  </link>
  <joint name="rear_right_hip_fe_joint" type="revolute">
    <origin rpy="0 0 3.141592653589793" xyz="0.0135 -0.0878 0"/>
    <axis xyz="1 0 0"/>
    <limit effort="2.5" lower="-0.17453292519943295" upper="0.7853981633974483" velocity="83.775"/>
    <dynamics damping="0.05" friction="0.1"/>
    <parent link="rear_right_hip_aa_link"/>
    <child link="rear_right_hip_fe_link"/>
  </joint>
  <transmission name="rear_right_hip_fe_transmission">
    <type>transmission_interface/SimpleTransmission</type>
    <joint name="rear_right_hip_fe_joint">
      <hardwareInterface>hardware_interface/EffortJointInterface</hardwareInterface>
    </joint>
    <actuator name="rear_right_hip_fe_motor">
      <hardwareInterface>hardware_interface/EffortJointInterface</hardwareInterface>
      <mechanicalReduction>1</mechanicalReduction>
    </actuator>
  </transmission>
  <link name="rear_right_upper_leg_link">
    <inertial>
      <mass value="0.160729"/>
      <origin xyz="0.000013 -0.0287 -0.069823"/>
      <inertia ixx="2.980E-04" ixy="6.814E-09" ixz="5.850E-08" iyy="2.986E-04" iyz="-3.241E-05" izz="2.929E-05"/>
    </inertial>
    <visual>
      <origin rpy="0 0 0" xyz="0 0 0"/>
      <geometry>
        <mesh filename="../meshes/leg/rear_right_upper_leg.stl" scale="0.001 0.001 0.001"/>
      </geometry>
    </visual>
    <collision>
      <origin rpy="0 0 0" xyz="0 0 0"/>
      <geometry>
        <mesh filename="../meshes/leg/rear_right_upper_leg.stl" scale="0.001 0.001 0.001"/>
      </geometry>
    </collision>
  </link>
  <joint name="rear_right_upper_leg_joint" type="revolute">
    <origin rpy="0 0 3.141592653589793" xyz="-0.0259 0.013 0"/>
    <axis xyz="0 1 0"/>
    <limit effort="2.5" lower="-1.5707963267948966" upper="1.5707963267948966" velocity="83.775"/>
    <dynamics damping="0.05" friction="0.1"/>
    <parent link="rear_right_hip_fe_link"/>
    <child link="rear_right_upper_leg_link"/>
  </joint>
  <transmission name="rear_right_upper_leg_transmission">
    <type>transmission_interface/SimpleTransmission</type>
    <joint name="rear_right_upper_leg_joint">
      <hardwareInterface>hardware_interface/EffortJointInterface</hardwareInterface>
    </joint>
    <actuator name="rear_right_upper_leg_motor">
      <hardwareInterface>hardware_interface/EffortJointInterface</hardwareInterface>
      <mechanicalReduction>1</mechanicalReduction>
    </actuator>
  </transmission>
  <link name="rear_right_lower_leg_link">
    <inertial>
      <mass value="0.028708"/>
      <origin xyz="0 -0.008269 -0.057302"/>
      <inertia ixx="6.697E-05" ixy="-5.712E-17" ixz="4.520E-16" iyy="6.678E-05" iyz="7.390E-06" izz="2.0798E-06"/>
    </inertial>
    <visual>
      <origin rpy="0 0 3.141592653589793" xyz="0 0 0"/>
      <geometry>
        <mesh filename="../meshes/leg/rear_lower_leg.stl" scale="0.001 0.001 0.001"/>
      </geometry>
    </visual>
    <collision>
      <origin rpy="0 0 3.141592653589793" xyz="0 0 0"/>
      <geometry>
        <mesh filename="../meshes/leg/rear_lower_leg.stl" scale="0.001 0.001 0.001"/>
      </geometry>
    </collision>
  </link>
  <joint name="rear_right_lower_leg_joint" type="revolute">
    <axis xyz="0 1 0"/>
    <limit effort="2.5" lower="-1.5707963267948966" upper="1.5707963267948966" velocity="83.775"/>
    <dynamics damping="0.05" friction="0.1"/>
    <origin rpy="0 0 0" xyz="0 -0.0285 -0.134"/>
    <parent link="rear_right_upper_leg_link"/>
    <child link="rear_right_lower_leg_link"/>
  </joint>
  <transmission name="rear_right_lower_leg_transmission">
    <type>transmission_interface/SimpleTransmission</type>
    <joint name="rear_right_lower_leg_joint">
      <hardwareInterface>hardware_interface/EffortJointInterface</hardwareInterface>
    </joint>
    <actuator name="rear_right_lower_leg_motor">
      <hardwareInterface>hardware_interface/EffortJointInterface</hardwareInterface>
      <mechanicalReduction>1</mechanicalReduction>
    </actuator>
  </transmission>
  <link name="rear_right_foot_contact_link">
    <inertial>
      <mass value="0.01"/>
      <origin xyz="0 0 0"/>
      <inertia ixx="1e-9" ixy="0.0" ixz="0.0" iyy="1e-9" iyz="0.0" izz="1e-9"/>
    </inertial>
    <visual>
      <origin xyz="0 0 0"/>
      <geometry>
        <sphere radius="0.015"/>
      </geometry>
    </visual>
    <collision>
      <origin xyz="0 0 0"/>
      <geometry>
        <sphere radius="0.015"/>
      </geometry>
    </collision>
  </link>
  <joint name="rear_right_foot_contact_joint" type="fixed">
    <origin xyz="0 0 -0.135"/>
    <parent link="rear_right_lower_leg_link"/>
    <child link="rear_right_foot_contact_link"/>
  </joint>
  <!--<xacro:neck/>-->
  <!--<xacro:head/>-->
</robot>

