<?xml version="1.0"?>
<robot name="two_wheel_walking_robot">
    <link name="base_link"/>

    <link name="chassis">
        <inertial>
            <origin xyz="0 0 0"/>
            <mass value="3.6"/>
            <inertia ixx="0.03075" iyy="0.06" izz="0.06675"
                     ixy="0.0"     ixz="0.0"  iyz="0.0"/>
        </inertial>
        <visual>
            <geometry>
                <box size="0.4 0.25 0.2"/>
            </geometry>
        </visual>
    </link>

    <joint name="base_link_to_chassis" type="fixed">
        <parent link="base_link"/>
        <child link="chassis"/>
    </joint>

    <link name="hip_roll_l">
        <collision>
            <geometry>
                <sphere radius="0.075"/>
            </geometry>
        </collision>
        <visual>
            <geometry>
                <sphere radius="0.075"/>
            </geometry>
        </visual>
    </link>

    <joint name="chassis_to_hip_roll_l" type="revolute">
        <origin rpy="0 0 0" xyz="0 0.1 -0.1"/>
        <axis xyz="1 0 0"/>
        <limit effort="30.0" lower="-0.2" upper="0.8" velocity="8.38"/>
        <parent link="chassis"/>
        <child link="hip_roll_l"/>
    </joint>

    <link name="hip_pitch_l">
        <collision>
            <origin xyz="0 0 -0.2125"/>
            <geometry>
                <box size="0.05 0.02 0.425"/>
            </geometry>
        </collision>
        <visual>
            <origin xyz="0 0 -0.2125"/>
            <geometry>
                <box size="0.05 0.02 0.425"/>
            </geometry>
        </visual>
    </link>

    <joint name="hip_roll_to_hip_pitch_l" type="revolute">
        <origin rpy="0 0 0" xyz="0 0 0"/>
        <axis xyz="0 1 0"/>
        <limit effort="30.0" lower="0" upper="1.3" velocity="8.38"/>
        <parent link="hip_roll_l"/>
        <child link="hip_pitch_l"/>
    </joint>

    <link name="knee_l">
        <collision>
            <origin xyz="0 0 -0.2125"/>
            <geometry>
                <box size="0.05 0.02 0.425"/>
            </geometry>
        </collision>
        <visual>
            <origin xyz="0 0 -0.2125"/>
            <geometry>
                <box size="0.05 0.02 0.425"/>
            </geometry>
        </visual>
    </link>

    <joint name="hip_pitch_to_knee_l" type="revolute">
        <origin rpy="0 0 0" xyz="0 0 -0.425"/>
        <axis xyz="0 1 0"/>
        <limit effort="30.0" lower="-2.6" upper="0" velocity="8.38"/>
        <parent link="hip_pitch_l"/>
        <child link="knee_l"/>
    </joint>

    <link name="wheel_l">
        <inertial>
            <mass value="0.8"/>
            <inertia ixx="0.00454" iyy="0.09" izz="0.00454"
                     ixy="0.0"     ixz="0.0"  iyz="0.0"/>
        </inertial>
        <collision>
            <origin rpy="1.57 0 0"/>
            <geometry>
                <cylinder length="0.025" radius="0.15"/>
            </geometry>
        </collision>
        <visual>
            <origin rpy="1.57 0 0"/>
            <geometry>
                <cylinder length="0.025" radius="0.15"/>
            </geometry>
        </visual>
    </link>

    <joint name="knee_to_wheel_l" type="continuous">
        <origin rpy="0 0 0" xyz="0 0 -0.425"/>
        <axis xyz="0 1 0"/>
        <limit effort="4.75" velocity="46.67"/>
        <parent link="knee_l"/>
        <child link="wheel_l"/>
    </joint>

    <link name="hip_roll_r">
        <collision>
            <geometry>
                <sphere radius="0.075"/>
            </geometry>
        </collision>
        <visual>
            <geometry>
                <sphere radius="0.075"/>
            </geometry>
        </visual>
    </link>

    <joint name="chassis_to_hip_roll_r" type="revolute">
        <origin rpy="0 0 0" xyz="0 -0.1 -0.1"/>
        <axis xyz="1 0 0"/>
        <limit effort="30.0" lower="-0.8" upper="0.2" velocity="8.38"/>
        <parent link="chassis"/>
        <child link="hip_roll_r"/>
    </joint>

    <link name="hip_pitch_r">
        <collision>
            <origin xyz="0 0 -0.2125"/>
            <geometry>
                <box size="0.05 0.02 0.425"/>
            </geometry>
        </collision>
        <visual>
            <origin xyz="0 0 -0.2125"/>
            <geometry>
                <box size="0.05 0.02 0.425"/>
            </geometry>
        </visual>
    </link>

    <joint name="hip_roll_to_hip_pitch_r" type="revolute">
        <origin rpy="0 0 0" xyz="0 0 0"/>
        <axis xyz="0 1 0"/>
        <limit effort="30.0" lower="0" upper="1.3" velocity="8.38"/>
        <parent link="hip_roll_r"/>
        <child link="hip_pitch_r"/>
    </joint>

    <link name="knee_r">
        <collision>
            <origin xyz="0 0 -0.2125"/>
            <geometry>
                <box size="0.05 0.02 0.425"/>
            </geometry>
        </collision>
        <visual>
            <origin xyz="0 0 -0.2125"/>
            <geometry>
                <box size="0.05 0.02 0.425"/>
            </geometry>
        </visual>
    </link>

    <joint name="hip_pitch_to_knee_r" type="revolute">
        <origin rpy="0 0 0" xyz="0 0 -0.425"/>
        <axis xyz="0 1 0"/>
        <limit effort="30.0" lower="-2.6" upper="0" velocity="8.38"/>
        <parent link="hip_pitch_r"/>
        <child link="knee_r"/>
    </joint>

    <link name="wheel_r">
        <inertial>
            <mass value="0.8"/>
            <inertia ixx="0.00454" iyy="0.09" izz="0.00454"
                     ixy="0.0"     ixz="0.0"  iyz="0.0"/>
        </inertial>
        <collision>
            <origin rpy="1.57 0 0"/>
            <geometry>
                <cylinder length="0.025" radius="0.15"/>
            </geometry>
        </collision>
        <visual>
            <origin rpy="1.57 0 0"/>
            <geometry>
                <cylinder length="0.025" radius="0.15"/>
            </geometry>
        </visual>
    </link>

    <joint name="knee_to_wheel_r" type="continuous">
        <origin rpy="0 0 0" xyz="0 0 -0.425"/>
        <axis xyz="0 1 0"/>
        <limit effort="4.75" velocity="46.67"/>
        <parent link="knee_r"/>
        <child link="wheel_r"/>
    </joint>
</robot>
